------------------------------------------------------------------
  Running MRIQC version 24.1.0.dev0+g3fe90466.d20240417
  ----------------------------------------------------------------
  * BIDS dataset path: /data.
  * Output folder: /out.
  * Analysis levels: ['participant'].
------------------------------------------------------------------

2024-08-04 22:05:01 | IMPORTANT | mriqc            | Building MRIQC's workflows...
2024-08-04 22:05:02 | IMPORTANT | mriqc            | DataLad dataset identified, attempting to `datalad get` unavailable files.
2024-08-04 22:05:03 | IMPORTANT | mriqc            | DataLad dataset identified, attempting to `datalad get` unavailable files.
2024-08-04 22:05:06 | IMPORTANT | mriqc            | Workflow building finished (exit code 0).
2024-08-04 22:05:09 | WARNING  | mriqc            | IMPORTANT: Anonymized quality metrics (IQMs) will be submitted to MRIQC's metrics repository. Submission of IQMs can be disabled using the ``--no-sub`` argument. Please visit https://mriqc.readthedocs.io/en/latest/dsa.html to revise MRIQC's Data Sharing Agreement.
2024-08-04 22:07:01 | ERROR    | concurrent.futures | exception calling callback for <Future at 0x7ffff5c12690 state=finished raised BrokenProcessPool>
Traceback (most recent call last):
  File "/opt/conda/lib/python3.11/concurrent/futures/_base.py", line 340, in _invoke_callbacks
    callback(self)
  File "/opt/conda/lib/python3.11/site-packages/mriqc/engine/plugin.py", line 456, in _async_callback
    result = args.result()
             ^^^^^^^^^^^^^
  File "/opt/conda/lib/python3.11/concurrent/futures/_base.py", line 449, in result
    return self.__get_result()
           ^^^^^^^^^^^^^^^^^^^
  File "/opt/conda/lib/python3.11/concurrent/futures/_base.py", line 401, in __get_result
    raise self._exception
concurrent.futures.process.BrokenProcessPool: A process in the process pool was terminated abruptly while the future was running or pending.
2024-08-04 22:07:02 | ERROR    | concurrent.futures | exception calling callback for <Future at 0x7fffeea64f90 state=finished raised BrokenProcessPool>
Traceback (most recent call last):
  File "/opt/conda/lib/python3.11/concurrent/futures/_base.py", line 340, in _invoke_callbacks
    callback(self)
  File "/opt/conda/lib/python3.11/site-packages/mriqc/engine/plugin.py", line 456, in _async_callback
    result = args.result()
             ^^^^^^^^^^^^^
  File "/opt/conda/lib/python3.11/concurrent/futures/_base.py", line 449, in result
    return self.__get_result()
           ^^^^^^^^^^^^^^^^^^^
  File "/opt/conda/lib/python3.11/concurrent/futures/_base.py", line 401, in __get_result
    raise self._exception
  File "/opt/conda/lib/python3.11/concurrent/futures/_base.py", line 340, in _invoke_callbacks
    callback(self)
  File "/opt/conda/lib/python3.11/site-packages/mriqc/engine/plugin.py", line 456, in _async_callback
    result = args.result()
             ^^^^^^^^^^^^^
  File "/opt/conda/lib/python3.11/concurrent/futures/_base.py", line 449, in result
    return self.__get_result()
           ^^^^^^^^^^^^^^^^^^^
  File "/opt/conda/lib/python3.11/concurrent/futures/_base.py", line 401, in __get_result
    raise self._exception
concurrent.futures.process.BrokenProcessPool: A process in the process pool was terminated abruptly while the future was running or pending.
2024-08-04 22:07:02 | ERROR    | concurrent.futures | exception calling callback for <Future at 0x7fffee90e1d0 state=finished raised BrokenProcessPool>
Traceback (most recent call last):
  File "/opt/conda/lib/python3.11/concurrent/futures/_base.py", line 340, in _invoke_callbacks
    callback(self)
  File "/opt/conda/lib/python3.11/site-packages/mriqc/engine/plugin.py", line 456, in _async_callback
    result = args.result()
             ^^^^^^^^^^^^^
  File "/opt/conda/lib/python3.11/concurrent/futures/_base.py", line 449, in result
    return self.__get_result()
           ^^^^^^^^^^^^^^^^^^^
  File "/opt/conda/lib/python3.11/concurrent/futures/_base.py", line 401, in __get_result
    raise self._exception
  File "/opt/conda/lib/python3.11/concurrent/futures/_base.py", line 340, in _invoke_callbacks
    callback(self)
  File "/opt/conda/lib/python3.11/site-packages/mriqc/engine/plugin.py", line 456, in _async_callback
    result = args.result()
             ^^^^^^^^^^^^^
  File "/opt/conda/lib/python3.11/concurrent/futures/_base.py", line 449, in result
    return self.__get_result()
           ^^^^^^^^^^^^^^^^^^^
  File "/opt/conda/lib/python3.11/concurrent/futures/_base.py", line 401, in __get_result
    raise self._exception
  File "/opt/conda/lib/python3.11/concurrent/futures/_base.py", line 340, in _invoke_callbacks
    callback(self)
  File "/opt/conda/lib/python3.11/site-packages/mriqc/engine/plugin.py", line 456, in _async_callback
    result = args.result()
             ^^^^^^^^^^^^^
  File "/opt/conda/lib/python3.11/concurrent/futures/_base.py", line 449, in result
    return self.__get_result()
           ^^^^^^^^^^^^^^^^^^^
  File "/opt/conda/lib/python3.11/concurrent/futures/_base.py", line 401, in __get_result
    raise self._exception
concurrent.futures.process.BrokenProcessPool: A process in the process pool was terminated abruptly while the future was running or pending.
2024-08-04 22:07:02 | ERROR    | concurrent.futures | exception calling callback for <Future at 0x7fffee8c5510 state=finished raised BrokenProcessPool>
Traceback (most recent call last):
  File "/opt/conda/lib/python3.11/concurrent/futures/_base.py", line 340, in _invoke_callbacks
    callback(self)
  File "/opt/conda/lib/python3.11/site-packages/mriqc/engine/plugin.py", line 456, in _async_callback
    result = args.result()
             ^^^^^^^^^^^^^
  File "/opt/conda/lib/python3.11/concurrent/futures/_base.py", line 449, in result
    return self.__get_result()
           ^^^^^^^^^^^^^^^^^^^
  File "/opt/conda/lib/python3.11/concurrent/futures/_base.py", line 401, in __get_result
    raise self._exception
  File "/opt/conda/lib/python3.11/concurrent/futures/_base.py", line 340, in _invoke_callbacks
    callback(self)
  File "/opt/conda/lib/python3.11/site-packages/mriqc/engine/plugin.py", line 456, in _async_callback
    result = args.result()
             ^^^^^^^^^^^^^
  File "/opt/conda/lib/python3.11/concurrent/futures/_base.py", line 449, in result
    return self.__get_result()
           ^^^^^^^^^^^^^^^^^^^
  File "/opt/conda/lib/python3.11/concurrent/futures/_base.py", line 401, in __get_result
    raise self._exception
  File "/opt/conda/lib/python3.11/concurrent/futures/_base.py", line 340, in _invoke_callbacks
    callback(self)
  File "/opt/conda/lib/python3.11/site-packages/mriqc/engine/plugin.py", line 456, in _async_callback
    result = args.result()
             ^^^^^^^^^^^^^
  File "/opt/conda/lib/python3.11/concurrent/futures/_base.py", line 449, in result
    return self.__get_result()
           ^^^^^^^^^^^^^^^^^^^
  File "/opt/conda/lib/python3.11/concurrent/futures/_base.py", line 401, in __get_result
    raise self._exception
  File "/opt/conda/lib/python3.11/concurrent/futures/_base.py", line 340, in _invoke_callbacks
    callback(self)
  File "/opt/conda/lib/python3.11/site-packages/mriqc/engine/plugin.py", line 456, in _async_callback
    result = args.result()
             ^^^^^^^^^^^^^
  File "/opt/conda/lib/python3.11/concurrent/futures/_base.py", line 449, in result
    return self.__get_result()
           ^^^^^^^^^^^^^^^^^^^
  File "/opt/conda/lib/python3.11/concurrent/futures/_base.py", line 401, in __get_result
    raise self._exception
concurrent.futures.process.BrokenProcessPool: A process in the process pool was terminated abruptly while the future was running or pending.
2024-08-04 22:07:02 | ERROR    | concurrent.futures | exception calling callback for <Future at 0x7fffee936550 state=finished raised BrokenProcessPool>
Traceback (most recent call last):
  File "/opt/conda/lib/python3.11/concurrent/futures/_base.py", line 340, in _invoke_callbacks
    callback(self)
  File "/opt/conda/lib/python3.11/site-packages/mriqc/engine/plugin.py", line 456, in _async_callback
    result = args.result()
             ^^^^^^^^^^^^^
  File "/opt/conda/lib/python3.11/concurrent/futures/_base.py", line 449, in result
    return self.__get_result()
           ^^^^^^^^^^^^^^^^^^^
  File "/opt/conda/lib/python3.11/concurrent/futures/_base.py", line 401, in __get_result
    raise self._exception
  File "/opt/conda/lib/python3.11/concurrent/futures/_base.py", line 340, in _invoke_callbacks
    callback(self)
  File "/opt/conda/lib/python3.11/site-packages/mriqc/engine/plugin.py", line 456, in _async_callback
    result = args.result()
             ^^^^^^^^^^^^^
  File "/opt/conda/lib/python3.11/concurrent/futures/_base.py", line 449, in result
    return self.__get_result()
           ^^^^^^^^^^^^^^^^^^^
  File "/opt/conda/lib/python3.11/concurrent/futures/_base.py", line 401, in __get_result
    raise self._exception
  File "/opt/conda/lib/python3.11/concurrent/futures/_base.py", line 340, in _invoke_callbacks
    callback(self)
  File "/opt/conda/lib/python3.11/site-packages/mriqc/engine/plugin.py", line 456, in _async_callback
    result = args.result()
             ^^^^^^^^^^^^^
  File "/opt/conda/lib/python3.11/concurrent/futures/_base.py", line 449, in result
    return self.__get_result()
           ^^^^^^^^^^^^^^^^^^^
  File "/opt/conda/lib/python3.11/concurrent/futures/_base.py", line 401, in __get_result
    raise self._exception
  File "/opt/conda/lib/python3.11/concurrent/futures/_base.py", line 340, in _invoke_callbacks
    callback(self)
  File "/opt/conda/lib/python3.11/site-packages/mriqc/engine/plugin.py", line 456, in _async_callback
    result = args.result()
             ^^^^^^^^^^^^^
  File "/opt/conda/lib/python3.11/concurrent/futures/_base.py", line 449, in result
    return self.__get_result()
           ^^^^^^^^^^^^^^^^^^^
  File "/opt/conda/lib/python3.11/concurrent/futures/_base.py", line 401, in __get_result
    raise self._exception
  File "/opt/conda/lib/python3.11/concurrent/futures/_base.py", line 340, in _invoke_callbacks
    callback(self)
  File "/opt/conda/lib/python3.11/site-packages/mriqc/engine/plugin.py", line 456, in _async_callback
    result = args.result()
             ^^^^^^^^^^^^^
  File "/opt/conda/lib/python3.11/concurrent/futures/_base.py", line 449, in result
    return self.__get_result()
           ^^^^^^^^^^^^^^^^^^^
  File "/opt/conda/lib/python3.11/concurrent/futures/_base.py", line 401, in __get_result
    raise self._exception
concurrent.futures.process.BrokenProcessPool: A process in the process pool was terminated abruptly while the future was running or pending.
2024-08-04 22:07:02 | ERROR    | concurrent.futures | exception calling callback for <Future at 0x7fffee8cd910 state=finished raised BrokenProcessPool>
Traceback (most recent call last):
  File "/opt/conda/lib/python3.11/concurrent/futures/_base.py", line 340, in _invoke_callbacks
    callback(self)
  File "/opt/conda/lib/python3.11/site-packages/mriqc/engine/plugin.py", line 456, in _async_callback
    result = args.result()
             ^^^^^^^^^^^^^
  File "/opt/conda/lib/python3.11/concurrent/futures/_base.py", line 449, in result
    return self.__get_result()
           ^^^^^^^^^^^^^^^^^^^
  File "/opt/conda/lib/python3.11/concurrent/futures/_base.py", line 401, in __get_result
    raise self._exception
  File "/opt/conda/lib/python3.11/concurrent/futures/_base.py", line 340, in _invoke_callbacks
    callback(self)
  File "/opt/conda/lib/python3.11/site-packages/mriqc/engine/plugin.py", line 456, in _async_callback
    result = args.result()
             ^^^^^^^^^^^^^
  File "/opt/conda/lib/python3.11/concurrent/futures/_base.py", line 449, in result
    return self.__get_result()
           ^^^^^^^^^^^^^^^^^^^
  File "/opt/conda/lib/python3.11/concurrent/futures/_base.py", line 401, in __get_result
    raise self._exception
  File "/opt/conda/lib/python3.11/concurrent/futures/_base.py", line 340, in _invoke_callbacks
    callback(self)
  File "/opt/conda/lib/python3.11/site-packages/mriqc/engine/plugin.py", line 456, in _async_callback
    result = args.result()
             ^^^^^^^^^^^^^
  File "/opt/conda/lib/python3.11/concurrent/futures/_base.py", line 449, in result
    return self.__get_result()
           ^^^^^^^^^^^^^^^^^^^
  File "/opt/conda/lib/python3.11/concurrent/futures/_base.py", line 401, in __get_result
    raise self._exception
  File "/opt/conda/lib/python3.11/concurrent/futures/_base.py", line 340, in _invoke_callbacks
    callback(self)
  File "/opt/conda/lib/python3.11/site-packages/mriqc/engine/plugin.py", line 456, in _async_callback
    result = args.result()
             ^^^^^^^^^^^^^
  File "/opt/conda/lib/python3.11/concurrent/futures/_base.py", line 449, in result
    return self.__get_result()
           ^^^^^^^^^^^^^^^^^^^
  File "/opt/conda/lib/python3.11/concurrent/futures/_base.py", line 401, in __get_result
    raise self._exception
  File "/opt/conda/lib/python3.11/concurrent/futures/_base.py", line 340, in _invoke_callbacks
    callback(self)
  File "/opt/conda/lib/python3.11/site-packages/mriqc/engine/plugin.py", line 456, in _async_callback
    result = args.result()
             ^^^^^^^^^^^^^
  File "/opt/conda/lib/python3.11/concurrent/futures/_base.py", line 449, in result
    return self.__get_result()
           ^^^^^^^^^^^^^^^^^^^
  File "/opt/conda/lib/python3.11/concurrent/futures/_base.py", line 401, in __get_result
    raise self._exception
  File "/opt/conda/lib/python3.11/concurrent/futures/_base.py", line 340, in _invoke_callbacks
    callback(self)
  File "/opt/conda/lib/python3.11/site-packages/mriqc/engine/plugin.py", line 456, in _async_callback
    result = args.result()
             ^^^^^^^^^^^^^
  File "/opt/conda/lib/python3.11/concurrent/futures/_base.py", line 449, in result
    return self.__get_result()
           ^^^^^^^^^^^^^^^^^^^
  File "/opt/conda/lib/python3.11/concurrent/futures/_base.py", line 401, in __get_result
    raise self._exception
concurrent.futures.process.BrokenProcessPool: A process in the process pool was terminated abruptly while the future was running or pending.
2024-08-04 22:07:02 | ERROR    | concurrent.futures | exception calling callback for <Future at 0x7fffee9176d0 state=finished raised BrokenProcessPool>
Traceback (most recent call last):
  File "/opt/conda/lib/python3.11/concurrent/futures/_base.py", line 340, in _invoke_callbacks
    callback(self)
  File "/opt/conda/lib/python3.11/site-packages/mriqc/engine/plugin.py", line 456, in _async_callback
    result = args.result()
             ^^^^^^^^^^^^^
  File "/opt/conda/lib/python3.11/concurrent/futures/_base.py", line 449, in result
    return self.__get_result()
           ^^^^^^^^^^^^^^^^^^^
  File "/opt/conda/lib/python3.11/concurrent/futures/_base.py", line 401, in __get_result
    raise self._exception
  File "/opt/conda/lib/python3.11/concurrent/futures/_base.py", line 340, in _invoke_callbacks
    callback(self)
  File "/opt/conda/lib/python3.11/site-packages/mriqc/engine/plugin.py", line 456, in _async_callback
    result = args.result()
             ^^^^^^^^^^^^^
  File "/opt/conda/lib/python3.11/concurrent/futures/_base.py", line 449, in result
    return self.__get_result()
           ^^^^^^^^^^^^^^^^^^^
  File "/opt/conda/lib/python3.11/concurrent/futures/_base.py", line 401, in __get_result
    raise self._exception
  File "/opt/conda/lib/python3.11/concurrent/futures/_base.py", line 340, in _invoke_callbacks
    callback(self)
  File "/opt/conda/lib/python3.11/site-packages/mriqc/engine/plugin.py", line 456, in _async_callback
    result = args.result()
             ^^^^^^^^^^^^^
  File "/opt/conda/lib/python3.11/concurrent/futures/_base.py", line 449, in result
    return self.__get_result()
           ^^^^^^^^^^^^^^^^^^^
  File "/opt/conda/lib/python3.11/concurrent/futures/_base.py", line 401, in __get_result
    raise self._exception
  File "/opt/conda/lib/python3.11/concurrent/futures/_base.py", line 340, in _invoke_callbacks
    callback(self)
  File "/opt/conda/lib/python3.11/site-packages/mriqc/engine/plugin.py", line 456, in _async_callback
    result = args.result()
             ^^^^^^^^^^^^^
  File "/opt/conda/lib/python3.11/concurrent/futures/_base.py", line 449, in result
    return self.__get_result()
           ^^^^^^^^^^^^^^^^^^^
  File "/opt/conda/lib/python3.11/concurrent/futures/_base.py", line 401, in __get_result
    raise self._exception
  File "/opt/conda/lib/python3.11/concurrent/futures/_base.py", line 340, in _invoke_callbacks
    callback(self)
  File "/opt/conda/lib/python3.11/site-packages/mriqc/engine/plugin.py", line 456, in _async_callback
    result = args.result()
             ^^^^^^^^^^^^^
  File "/opt/conda/lib/python3.11/concurrent/futures/_base.py", line 449, in result
    return self.__get_result()
           ^^^^^^^^^^^^^^^^^^^
  File "/opt/conda/lib/python3.11/concurrent/futures/_base.py", line 401, in __get_result
    raise self._exception
  File "/opt/conda/lib/python3.11/concurrent/futures/_base.py", line 340, in _invoke_callbacks
    callback(self)
  File "/opt/conda/lib/python3.11/site-packages/mriqc/engine/plugin.py", line 456, in _async_callback
    result = args.result()
             ^^^^^^^^^^^^^
  File "/opt/conda/lib/python3.11/concurrent/futures/_base.py", line 449, in result
    return self.__get_result()
           ^^^^^^^^^^^^^^^^^^^
  File "/opt/conda/lib/python3.11/concurrent/futures/_base.py", line 401, in __get_result
    raise self._exception
  File "/opt/conda/lib/python3.11/concurrent/futures/_base.py", line 340, in _invoke_callbacks
    callback(self)
  File "/opt/conda/lib/python3.11/site-packages/mriqc/engine/plugin.py", line 456, in _async_callback
    result = args.result()
             ^^^^^^^^^^^^^
  File "/opt/conda/lib/python3.11/concurrent/futures/_base.py", line 449, in result
    return self.__get_result()
           ^^^^^^^^^^^^^^^^^^^
  File "/opt/conda/lib/python3.11/concurrent/futures/_base.py", line 401, in __get_result
    raise self._exception
concurrent.futures.process.BrokenProcessPool: A process in the process pool was terminated abruptly while the future was running or pending.
2024-08-04 22:07:02 | ERROR    | concurrent.futures | exception calling callback for <Future at 0x7fffee91b790 state=finished raised BrokenProcessPool>
Traceback (most recent call last):
  File "/opt/conda/lib/python3.11/concurrent/futures/_base.py", line 340, in _invoke_callbacks
    callback(self)
  File "/opt/conda/lib/python3.11/site-packages/mriqc/engine/plugin.py", line 456, in _async_callback
    result = args.result()
             ^^^^^^^^^^^^^
  File "/opt/conda/lib/python3.11/concurrent/futures/_base.py", line 449, in result
    return self.__get_result()
           ^^^^^^^^^^^^^^^^^^^
  File "/opt/conda/lib/python3.11/concurrent/futures/_base.py", line 401, in __get_result
    raise self._exception
  File "/opt/conda/lib/python3.11/concurrent/futures/_base.py", line 340, in _invoke_callbacks
    callback(self)
  File "/opt/conda/lib/python3.11/site-packages/mriqc/engine/plugin.py", line 456, in _async_callback
    result = args.result()
             ^^^^^^^^^^^^^
  File "/opt/conda/lib/python3.11/concurrent/futures/_base.py", line 449, in result
    return self.__get_result()
           ^^^^^^^^^^^^^^^^^^^
  File "/opt/conda/lib/python3.11/concurrent/futures/_base.py", line 401, in __get_result
    raise self._exception
  File "/opt/conda/lib/python3.11/concurrent/futures/_base.py", line 340, in _invoke_callbacks
    callback(self)
  File "/opt/conda/lib/python3.11/site-packages/mriqc/engine/plugin.py", line 456, in _async_callback
    result = args.result()
             ^^^^^^^^^^^^^
  File "/opt/conda/lib/python3.11/concurrent/futures/_base.py", line 449, in result
    return self.__get_result()
           ^^^^^^^^^^^^^^^^^^^
  File "/opt/conda/lib/python3.11/concurrent/futures/_base.py", line 401, in __get_result
    raise self._exception
  File "/opt/conda/lib/python3.11/concurrent/futures/_base.py", line 340, in _invoke_callbacks
    callback(self)
  File "/opt/conda/lib/python3.11/site-packages/mriqc/engine/plugin.py", line 456, in _async_callback
    result = args.result()
             ^^^^^^^^^^^^^
  File "/opt/conda/lib/python3.11/concurrent/futures/_base.py", line 449, in result
    return self.__get_result()
           ^^^^^^^^^^^^^^^^^^^
  File "/opt/conda/lib/python3.11/concurrent/futures/_base.py", line 401, in __get_result
    raise self._exception
  File "/opt/conda/lib/python3.11/concurrent/futures/_base.py", line 340, in _invoke_callbacks
    callback(self)
  File "/opt/conda/lib/python3.11/site-packages/mriqc/engine/plugin.py", line 456, in _async_callback
    result = args.result()
             ^^^^^^^^^^^^^
  File "/opt/conda/lib/python3.11/concurrent/futures/_base.py", line 449, in result
    return self.__get_result()
           ^^^^^^^^^^^^^^^^^^^
  File "/opt/conda/lib/python3.11/concurrent/futures/_base.py", line 401, in __get_result
    raise self._exception
  File "/opt/conda/lib/python3.11/concurrent/futures/_base.py", line 340, in _invoke_callbacks
    callback(self)
  File "/opt/conda/lib/python3.11/site-packages/mriqc/engine/plugin.py", line 456, in _async_callback
    result = args.result()
             ^^^^^^^^^^^^^
  File "/opt/conda/lib/python3.11/concurrent/futures/_base.py", line 449, in result
    return self.__get_result()
           ^^^^^^^^^^^^^^^^^^^
  File "/opt/conda/lib/python3.11/concurrent/futures/_base.py", line 401, in __get_result
    raise self._exception
  File "/opt/conda/lib/python3.11/concurrent/futures/_base.py", line 340, in _invoke_callbacks
    callback(self)
  File "/opt/conda/lib/python3.11/site-packages/mriqc/engine/plugin.py", line 456, in _async_callback
    result = args.result()
             ^^^^^^^^^^^^^
  File "/opt/conda/lib/python3.11/concurrent/futures/_base.py", line 449, in result
    return self.__get_result()
           ^^^^^^^^^^^^^^^^^^^
  File "/opt/conda/lib/python3.11/concurrent/futures/_base.py", line 401, in __get_result
    raise self._exception
  File "/opt/conda/lib/python3.11/concurrent/futures/_base.py", line 340, in _invoke_callbacks
    callback(self)
  File "/opt/conda/lib/python3.11/site-packages/mriqc/engine/plugin.py", line 456, in _async_callback
    result = args.result()
             ^^^^^^^^^^^^^
  File "/opt/conda/lib/python3.11/concurrent/futures/_base.py", line 449, in result
    return self.__get_result()
           ^^^^^^^^^^^^^^^^^^^
  File "/opt/conda/lib/python3.11/concurrent/futures/_base.py", line 401, in __get_result
    raise self._exception
concurrent.futures.process.BrokenProcessPool: A process in the process pool was terminated abruptly while the future was running or pending.
2024-08-04 22:07:02 | ERROR    | concurrent.futures | exception calling callback for <Future at 0x7fffeeaacad0 state=finished raised BrokenProcessPool>
Traceback (most recent call last):
  File "/opt/conda/lib/python3.11/concurrent/futures/_base.py", line 340, in _invoke_callbacks
    callback(self)
  File "/opt/conda/lib/python3.11/site-packages/mriqc/engine/plugin.py", line 456, in _async_callback
    result = args.result()
             ^^^^^^^^^^^^^
  File "/opt/conda/lib/python3.11/concurrent/futures/_base.py", line 449, in result
    return self.__get_result()
           ^^^^^^^^^^^^^^^^^^^
  File "/opt/conda/lib/python3.11/concurrent/futures/_base.py", line 401, in __get_result
    raise self._exception
  File "/opt/conda/lib/python3.11/concurrent/futures/_base.py", line 340, in _invoke_callbacks
    callback(self)
  File "/opt/conda/lib/python3.11/site-packages/mriqc/engine/plugin.py", line 456, in _async_callback
    result = args.result()
             ^^^^^^^^^^^^^
  File "/opt/conda/lib/python3.11/concurrent/futures/_base.py", line 449, in result
    return self.__get_result()
           ^^^^^^^^^^^^^^^^^^^
  File "/opt/conda/lib/python3.11/concurrent/futures/_base.py", line 401, in __get_result
    raise self._exception
  File "/opt/conda/lib/python3.11/concurrent/futures/_base.py", line 340, in _invoke_callbacks
    callback(self)
  File "/opt/conda/lib/python3.11/site-packages/mriqc/engine/plugin.py", line 456, in _async_callback
    result = args.result()
             ^^^^^^^^^^^^^
  File "/opt/conda/lib/python3.11/concurrent/futures/_base.py", line 449, in result
    return self.__get_result()
           ^^^^^^^^^^^^^^^^^^^
  File "/opt/conda/lib/python3.11/concurrent/futures/_base.py", line 401, in __get_result
    raise self._exception
  File "/opt/conda/lib/python3.11/concurrent/futures/_base.py", line 340, in _invoke_callbacks
    callback(self)
  File "/opt/conda/lib/python3.11/site-packages/mriqc/engine/plugin.py", line 456, in _async_callback
    result = args.result()
             ^^^^^^^^^^^^^
  File "/opt/conda/lib/python3.11/concurrent/futures/_base.py", line 449, in result
    return self.__get_result()
           ^^^^^^^^^^^^^^^^^^^
  File "/opt/conda/lib/python3.11/concurrent/futures/_base.py", line 401, in __get_result
    raise self._exception
  File "/opt/conda/lib/python3.11/concurrent/futures/_base.py", line 340, in _invoke_callbacks
    callback(self)
  File "/opt/conda/lib/python3.11/site-packages/mriqc/engine/plugin.py", line 456, in _async_callback
    result = args.result()
             ^^^^^^^^^^^^^
  File "/opt/conda/lib/python3.11/concurrent/futures/_base.py", line 449, in result
    return self.__get_result()
           ^^^^^^^^^^^^^^^^^^^
  File "/opt/conda/lib/python3.11/concurrent/futures/_base.py", line 401, in __get_result
    raise self._exception
  File "/opt/conda/lib/python3.11/concurrent/futures/_base.py", line 340, in _invoke_callbacks
    callback(self)
  File "/opt/conda/lib/python3.11/site-packages/mriqc/engine/plugin.py", line 456, in _async_callback
    result = args.result()
             ^^^^^^^^^^^^^
  File "/opt/conda/lib/python3.11/concurrent/futures/_base.py", line 449, in result
    return self.__get_result()
           ^^^^^^^^^^^^^^^^^^^
  File "/opt/conda/lib/python3.11/concurrent/futures/_base.py", line 401, in __get_result
    raise self._exception
  File "/opt/conda/lib/python3.11/concurrent/futures/_base.py", line 340, in _invoke_callbacks
    callback(self)
  File "/opt/conda/lib/python3.11/site-packages/mriqc/engine/plugin.py", line 456, in _async_callback
    result = args.result()
             ^^^^^^^^^^^^^
  File "/opt/conda/lib/python3.11/concurrent/futures/_base.py", line 449, in result
    return self.__get_result()
           ^^^^^^^^^^^^^^^^^^^
  File "/opt/conda/lib/python3.11/concurrent/futures/_base.py", line 401, in __get_result
    raise self._exception
  File "/opt/conda/lib/python3.11/concurrent/futures/_base.py", line 340, in _invoke_callbacks
    callback(self)
  File "/opt/conda/lib/python3.11/site-packages/mriqc/engine/plugin.py", line 456, in _async_callback
    result = args.result()
             ^^^^^^^^^^^^^
  File "/opt/conda/lib/python3.11/concurrent/futures/_base.py", line 449, in result
    return self.__get_result()
           ^^^^^^^^^^^^^^^^^^^
  File "/opt/conda/lib/python3.11/concurrent/futures/_base.py", line 401, in __get_result
    raise self._exception
  File "/opt/conda/lib/python3.11/concurrent/futures/_base.py", line 340, in _invoke_callbacks
    callback(self)
  File "/opt/conda/lib/python3.11/site-packages/mriqc/engine/plugin.py", line 456, in _async_callback
    result = args.result()
             ^^^^^^^^^^^^^
  File "/opt/conda/lib/python3.11/concurrent/futures/_base.py", line 449, in result
    return self.__get_result()
           ^^^^^^^^^^^^^^^^^^^
  File "/opt/conda/lib/python3.11/concurrent/futures/_base.py", line 401, in __get_result
    raise self._exception
concurrent.futures.process.BrokenProcessPool: A process in the process pool was terminated abruptly while the future was running or pending.
2024-08-04 22:07:02 | ERROR    | concurrent.futures | exception calling callback for <Future at 0x7fffee917510 state=finished raised BrokenProcessPool>
Traceback (most recent call last):
  File "/opt/conda/lib/python3.11/concurrent/futures/_base.py", line 340, in _invoke_callbacks
    callback(self)
  File "/opt/conda/lib/python3.11/site-packages/mriqc/engine/plugin.py", line 456, in _async_callback
    result = args.result()
             ^^^^^^^^^^^^^
  File "/opt/conda/lib/python3.11/concurrent/futures/_base.py", line 449, in result
    return self.__get_result()
           ^^^^^^^^^^^^^^^^^^^
  File "/opt/conda/lib/python3.11/concurrent/futures/_base.py", line 401, in __get_result
    raise self._exception
  File "/opt/conda/lib/python3.11/concurrent/futures/_base.py", line 340, in _invoke_callbacks
    callback(self)
  File "/opt/conda/lib/python3.11/site-packages/mriqc/engine/plugin.py", line 456, in _async_callback
    result = args.result()
             ^^^^^^^^^^^^^
  File "/opt/conda/lib/python3.11/concurrent/futures/_base.py", line 449, in result
    return self.__get_result()
           ^^^^^^^^^^^^^^^^^^^
  File "/opt/conda/lib/python3.11/concurrent/futures/_base.py", line 401, in __get_result
    raise self._exception
  File "/opt/conda/lib/python3.11/concurrent/futures/_base.py", line 340, in _invoke_callbacks
    callback(self)
  File "/opt/conda/lib/python3.11/site-packages/mriqc/engine/plugin.py", line 456, in _async_callback
    result = args.result()
             ^^^^^^^^^^^^^
  File "/opt/conda/lib/python3.11/concurrent/futures/_base.py", line 449, in result
    return self.__get_result()
           ^^^^^^^^^^^^^^^^^^^
  File "/opt/conda/lib/python3.11/concurrent/futures/_base.py", line 401, in __get_result
    raise self._exception
  File "/opt/conda/lib/python3.11/concurrent/futures/_base.py", line 340, in _invoke_callbacks
    callback(self)
  File "/opt/conda/lib/python3.11/site-packages/mriqc/engine/plugin.py", line 456, in _async_callback
    result = args.result()
             ^^^^^^^^^^^^^
  File "/opt/conda/lib/python3.11/concurrent/futures/_base.py", line 449, in result
    return self.__get_result()
           ^^^^^^^^^^^^^^^^^^^
  File "/opt/conda/lib/python3.11/concurrent/futures/_base.py", line 401, in __get_result
    raise self._exception
  File "/opt/conda/lib/python3.11/concurrent/futures/_base.py", line 340, in _invoke_callbacks
    callback(self)
  File "/opt/conda/lib/python3.11/site-packages/mriqc/engine/plugin.py", line 456, in _async_callback
    result = args.result()
             ^^^^^^^^^^^^^
  File "/opt/conda/lib/python3.11/concurrent/futures/_base.py", line 449, in result
    return self.__get_result()
           ^^^^^^^^^^^^^^^^^^^
  File "/opt/conda/lib/python3.11/concurrent/futures/_base.py", line 401, in __get_result
    raise self._exception
  File "/opt/conda/lib/python3.11/concurrent/futures/_base.py", line 340, in _invoke_callbacks
    callback(self)
  File "/opt/conda/lib/python3.11/site-packages/mriqc/engine/plugin.py", line 456, in _async_callback
    result = args.result()
             ^^^^^^^^^^^^^
  File "/opt/conda/lib/python3.11/concurrent/futures/_base.py", line 449, in result
    return self.__get_result()
           ^^^^^^^^^^^^^^^^^^^
  File "/opt/conda/lib/python3.11/concurrent/futures/_base.py", line 401, in __get_result
    raise self._exception
  File "/opt/conda/lib/python3.11/concurrent/futures/_base.py", line 340, in _invoke_callbacks
    callback(self)
  File "/opt/conda/lib/python3.11/site-packages/mriqc/engine/plugin.py", line 456, in _async_callback
    result = args.result()
             ^^^^^^^^^^^^^
  File "/opt/conda/lib/python3.11/concurrent/futures/_base.py", line 449, in result
    return self.__get_result()
           ^^^^^^^^^^^^^^^^^^^
  File "/opt/conda/lib/python3.11/concurrent/futures/_base.py", line 401, in __get_result
    raise self._exception
  File "/opt/conda/lib/python3.11/concurrent/futures/_base.py", line 340, in _invoke_callbacks
    callback(self)
  File "/opt/conda/lib/python3.11/site-packages/mriqc/engine/plugin.py", line 456, in _async_callback
    result = args.result()
             ^^^^^^^^^^^^^
  File "/opt/conda/lib/python3.11/concurrent/futures/_base.py", line 449, in result
    return self.__get_result()
           ^^^^^^^^^^^^^^^^^^^
  File "/opt/conda/lib/python3.11/concurrent/futures/_base.py", line 401, in __get_result
    raise self._exception
  File "/opt/conda/lib/python3.11/concurrent/futures/_base.py", line 340, in _invoke_callbacks
    callback(self)
  File "/opt/conda/lib/python3.11/site-packages/mriqc/engine/plugin.py", line 456, in _async_callback
    result = args.result()
             ^^^^^^^^^^^^^
  File "/opt/conda/lib/python3.11/concurrent/futures/_base.py", line 449, in result
    return self.__get_result()
           ^^^^^^^^^^^^^^^^^^^
  File "/opt/conda/lib/python3.11/concurrent/futures/_base.py", line 401, in __get_result
    raise self._exception
  File "/opt/conda/lib/python3.11/concurrent/futures/_base.py", line 340, in _invoke_callbacks
    callback(self)
  File "/opt/conda/lib/python3.11/site-packages/mriqc/engine/plugin.py", line 456, in _async_callback
    result = args.result()
             ^^^^^^^^^^^^^
  File "/opt/conda/lib/python3.11/concurrent/futures/_base.py", line 449, in result
    return self.__get_result()
           ^^^^^^^^^^^^^^^^^^^
  File "/opt/conda/lib/python3.11/concurrent/futures/_base.py", line 401, in __get_result
    raise self._exception
concurrent.futures.process.BrokenProcessPool: A process in the process pool was terminated abruptly while the future was running or pending.
2024-08-04 22:07:02 | ERROR    | concurrent.futures | exception calling callback for <Future at 0x7fffed74a5d0 state=finished raised BrokenProcessPool>
Traceback (most recent call last):
  File "/opt/conda/lib/python3.11/concurrent/futures/_base.py", line 340, in _invoke_callbacks
    callback(self)
  File "/opt/conda/lib/python3.11/site-packages/mriqc/engine/plugin.py", line 456, in _async_callback
    result = args.result()
             ^^^^^^^^^^^^^
  File "/opt/conda/lib/python3.11/concurrent/futures/_base.py", line 449, in result
    return self.__get_result()
           ^^^^^^^^^^^^^^^^^^^
  File "/opt/conda/lib/python3.11/concurrent/futures/_base.py", line 401, in __get_result
    raise self._exception
  File "/opt/conda/lib/python3.11/concurrent/futures/_base.py", line 340, in _invoke_callbacks
    callback(self)
  File "/opt/conda/lib/python3.11/site-packages/mriqc/engine/plugin.py", line 456, in _async_callback
    result = args.result()
             ^^^^^^^^^^^^^
  File "/opt/conda/lib/python3.11/concurrent/futures/_base.py", line 449, in result
    return self.__get_result()
           ^^^^^^^^^^^^^^^^^^^
  File "/opt/conda/lib/python3.11/concurrent/futures/_base.py", line 401, in __get_result
    raise self._exception
  File "/opt/conda/lib/python3.11/concurrent/futures/_base.py", line 340, in _invoke_callbacks
    callback(self)
  File "/opt/conda/lib/python3.11/site-packages/mriqc/engine/plugin.py", line 456, in _async_callback
    result = args.result()
             ^^^^^^^^^^^^^
  File "/opt/conda/lib/python3.11/concurrent/futures/_base.py", line 449, in result
    return self.__get_result()
           ^^^^^^^^^^^^^^^^^^^
  File "/opt/conda/lib/python3.11/concurrent/futures/_base.py", line 401, in __get_result
    raise self._exception
  File "/opt/conda/lib/python3.11/concurrent/futures/_base.py", line 340, in _invoke_callbacks
    callback(self)
  File "/opt/conda/lib/python3.11/site-packages/mriqc/engine/plugin.py", line 456, in _async_callback
    result = args.result()
             ^^^^^^^^^^^^^
  File "/opt/conda/lib/python3.11/concurrent/futures/_base.py", line 449, in result
    return self.__get_result()
           ^^^^^^^^^^^^^^^^^^^
  File "/opt/conda/lib/python3.11/concurrent/futures/_base.py", line 401, in __get_result
    raise self._exception
  File "/opt/conda/lib/python3.11/concurrent/futures/_base.py", line 340, in _invoke_callbacks
    callback(self)
  File "/opt/conda/lib/python3.11/site-packages/mriqc/engine/plugin.py", line 456, in _async_callback
    result = args.result()
             ^^^^^^^^^^^^^
  File "/opt/conda/lib/python3.11/concurrent/futures/_base.py", line 449, in result
    return self.__get_result()
           ^^^^^^^^^^^^^^^^^^^
  File "/opt/conda/lib/python3.11/concurrent/futures/_base.py", line 401, in __get_result
    raise self._exception
  File "/opt/conda/lib/python3.11/concurrent/futures/_base.py", line 340, in _invoke_callbacks
    callback(self)
  File "/opt/conda/lib/python3.11/site-packages/mriqc/engine/plugin.py", line 456, in _async_callback
    result = args.result()
             ^^^^^^^^^^^^^
  File "/opt/conda/lib/python3.11/concurrent/futures/_base.py", line 449, in result
    return self.__get_result()
           ^^^^^^^^^^^^^^^^^^^
  File "/opt/conda/lib/python3.11/concurrent/futures/_base.py", line 401, in __get_result
    raise self._exception
  File "/opt/conda/lib/python3.11/concurrent/futures/_base.py", line 340, in _invoke_callbacks
    callback(self)
  File "/opt/conda/lib/python3.11/site-packages/mriqc/engine/plugin.py", line 456, in _async_callback
    result = args.result()
             ^^^^^^^^^^^^^
  File "/opt/conda/lib/python3.11/concurrent/futures/_base.py", line 449, in result
    return self.__get_result()
           ^^^^^^^^^^^^^^^^^^^
  File "/opt/conda/lib/python3.11/concurrent/futures/_base.py", line 401, in __get_result
    raise self._exception
  File "/opt/conda/lib/python3.11/concurrent/futures/_base.py", line 340, in _invoke_callbacks
    callback(self)
  File "/opt/conda/lib/python3.11/site-packages/mriqc/engine/plugin.py", line 456, in _async_callback
    result = args.result()
             ^^^^^^^^^^^^^
  File "/opt/conda/lib/python3.11/concurrent/futures/_base.py", line 449, in result
    return self.__get_result()
           ^^^^^^^^^^^^^^^^^^^
  File "/opt/conda/lib/python3.11/concurrent/futures/_base.py", line 401, in __get_result
    raise self._exception
  File "/opt/conda/lib/python3.11/concurrent/futures/_base.py", line 340, in _invoke_callbacks
    callback(self)
  File "/opt/conda/lib/python3.11/site-packages/mriqc/engine/plugin.py", line 456, in _async_callback
    result = args.result()
             ^^^^^^^^^^^^^
  File "/opt/conda/lib/python3.11/concurrent/futures/_base.py", line 449, in result
    return self.__get_result()
           ^^^^^^^^^^^^^^^^^^^
  File "/opt/conda/lib/python3.11/concurrent/futures/_base.py", line 401, in __get_result
    raise self._exception
  File "/opt/conda/lib/python3.11/concurrent/futures/_base.py", line 340, in _invoke_callbacks
    callback(self)
  File "/opt/conda/lib/python3.11/site-packages/mriqc/engine/plugin.py", line 456, in _async_callback
    result = args.result()
             ^^^^^^^^^^^^^
  File "/opt/conda/lib/python3.11/concurrent/futures/_base.py", line 449, in result
    return self.__get_result()
           ^^^^^^^^^^^^^^^^^^^
  File "/opt/conda/lib/python3.11/concurrent/futures/_base.py", line 401, in __get_result
    raise self._exception
  File "/opt/conda/lib/python3.11/concurrent/futures/_base.py", line 340, in _invoke_callbacks
    callback(self)
  File "/opt/conda/lib/python3.11/site-packages/mriqc/engine/plugin.py", line 456, in _async_callback
    result = args.result()
             ^^^^^^^^^^^^^
  File "/opt/conda/lib/python3.11/concurrent/futures/_base.py", line 449, in result
    return self.__get_result()
           ^^^^^^^^^^^^^^^^^^^
  File "/opt/conda/lib/python3.11/concurrent/futures/_base.py", line 401, in __get_result
    raise self._exception
concurrent.futures.process.BrokenProcessPool: A process in the process pool was terminated abruptly while the future was running or pending.
2024-08-04 22:07:02 | ERROR    | concurrent.futures | exception calling callback for <Future at 0x7fffed75ac50 state=finished raised BrokenProcessPool>
Traceback (most recent call last):
  File "/opt/conda/lib/python3.11/concurrent/futures/_base.py", line 340, in _invoke_callbacks
    callback(self)
  File "/opt/conda/lib/python3.11/site-packages/mriqc/engine/plugin.py", line 456, in _async_callback
    result = args.result()
             ^^^^^^^^^^^^^
  File "/opt/conda/lib/python3.11/concurrent/futures/_base.py", line 449, in result
    return self.__get_result()
           ^^^^^^^^^^^^^^^^^^^
  File "/opt/conda/lib/python3.11/concurrent/futures/_base.py", line 401, in __get_result
    raise self._exception
  File "/opt/conda/lib/python3.11/concurrent/futures/_base.py", line 340, in _invoke_callbacks
    callback(self)
  File "/opt/conda/lib/python3.11/site-packages/mriqc/engine/plugin.py", line 456, in _async_callback
    result = args.result()
             ^^^^^^^^^^^^^
  File "/opt/conda/lib/python3.11/concurrent/futures/_base.py", line 449, in result
    return self.__get_result()
           ^^^^^^^^^^^^^^^^^^^
  File "/opt/conda/lib/python3.11/concurrent/futures/_base.py", line 401, in __get_result
    raise self._exception
  File "/opt/conda/lib/python3.11/concurrent/futures/_base.py", line 340, in _invoke_callbacks
    callback(self)
  File "/opt/conda/lib/python3.11/site-packages/mriqc/engine/plugin.py", line 456, in _async_callback
    result = args.result()
             ^^^^^^^^^^^^^
  File "/opt/conda/lib/python3.11/concurrent/futures/_base.py", line 449, in result
    return self.__get_result()
           ^^^^^^^^^^^^^^^^^^^
  File "/opt/conda/lib/python3.11/concurrent/futures/_base.py", line 401, in __get_result
    raise self._exception
  File "/opt/conda/lib/python3.11/concurrent/futures/_base.py", line 340, in _invoke_callbacks
    callback(self)
  File "/opt/conda/lib/python3.11/site-packages/mriqc/engine/plugin.py", line 456, in _async_callback
    result = args.result()
             ^^^^^^^^^^^^^
  File "/opt/conda/lib/python3.11/concurrent/futures/_base.py", line 449, in result
    return self.__get_result()
           ^^^^^^^^^^^^^^^^^^^
  File "/opt/conda/lib/python3.11/concurrent/futures/_base.py", line 401, in __get_result
    raise self._exception
  File "/opt/conda/lib/python3.11/concurrent/futures/_base.py", line 340, in _invoke_callbacks
    callback(self)
  File "/opt/conda/lib/python3.11/site-packages/mriqc/engine/plugin.py", line 456, in _async_callback
    result = args.result()
             ^^^^^^^^^^^^^
  File "/opt/conda/lib/python3.11/concurrent/futures/_base.py", line 449, in result
    return self.__get_result()
           ^^^^^^^^^^^^^^^^^^^
  File "/opt/conda/lib/python3.11/concurrent/futures/_base.py", line 401, in __get_result
    raise self._exception
  File "/opt/conda/lib/python3.11/concurrent/futures/_base.py", line 340, in _invoke_callbacks
    callback(self)
  File "/opt/conda/lib/python3.11/site-packages/mriqc/engine/plugin.py", line 456, in _async_callback
    result = args.result()
             ^^^^^^^^^^^^^
  File "/opt/conda/lib/python3.11/concurrent/futures/_base.py", line 449, in result
    return self.__get_result()
           ^^^^^^^^^^^^^^^^^^^
  File "/opt/conda/lib/python3.11/concurrent/futures/_base.py", line 401, in __get_result
    raise self._exception
  File "/opt/conda/lib/python3.11/concurrent/futures/_base.py", line 340, in _invoke_callbacks
    callback(self)
  File "/opt/conda/lib/python3.11/site-packages/mriqc/engine/plugin.py", line 456, in _async_callback
    result = args.result()
             ^^^^^^^^^^^^^
  File "/opt/conda/lib/python3.11/concurrent/futures/_base.py", line 449, in result
    return self.__get_result()
           ^^^^^^^^^^^^^^^^^^^
  File "/opt/conda/lib/python3.11/concurrent/futures/_base.py", line 401, in __get_result
    raise self._exception
  File "/opt/conda/lib/python3.11/concurrent/futures/_base.py", line 340, in _invoke_callbacks
    callback(self)
  File "/opt/conda/lib/python3.11/site-packages/mriqc/engine/plugin.py", line 456, in _async_callback
    result = args.result()
             ^^^^^^^^^^^^^
  File "/opt/conda/lib/python3.11/concurrent/futures/_base.py", line 449, in result
    return self.__get_result()
           ^^^^^^^^^^^^^^^^^^^
  File "/opt/conda/lib/python3.11/concurrent/futures/_base.py", line 401, in __get_result
    raise self._exception
  File "/opt/conda/lib/python3.11/concurrent/futures/_base.py", line 340, in _invoke_callbacks
    callback(self)
  File "/opt/conda/lib/python3.11/site-packages/mriqc/engine/plugin.py", line 456, in _async_callback
    result = args.result()
             ^^^^^^^^^^^^^
  File "/opt/conda/lib/python3.11/concurrent/futures/_base.py", line 449, in result
    return self.__get_result()
           ^^^^^^^^^^^^^^^^^^^
  File "/opt/conda/lib/python3.11/concurrent/futures/_base.py", line 401, in __get_result
    raise self._exception
  File "/opt/conda/lib/python3.11/concurrent/futures/_base.py", line 340, in _invoke_callbacks
    callback(self)
  File "/opt/conda/lib/python3.11/site-packages/mriqc/engine/plugin.py", line 456, in _async_callback
    result = args.result()
             ^^^^^^^^^^^^^
  File "/opt/conda/lib/python3.11/concurrent/futures/_base.py", line 449, in result
    return self.__get_result()
           ^^^^^^^^^^^^^^^^^^^
  File "/opt/conda/lib/python3.11/concurrent/futures/_base.py", line 401, in __get_result
    raise self._exception
  File "/opt/conda/lib/python3.11/concurrent/futures/_base.py", line 340, in _invoke_callbacks
    callback(self)
  File "/opt/conda/lib/python3.11/site-packages/mriqc/engine/plugin.py", line 456, in _async_callback
    result = args.result()
             ^^^^^^^^^^^^^
  File "/opt/conda/lib/python3.11/concurrent/futures/_base.py", line 449, in result
    return self.__get_result()
           ^^^^^^^^^^^^^^^^^^^
  File "/opt/conda/lib/python3.11/concurrent/futures/_base.py", line 401, in __get_result
    raise self._exception
  File "/opt/conda/lib/python3.11/concurrent/futures/_base.py", line 340, in _invoke_callbacks
    callback(self)
  File "/opt/conda/lib/python3.11/site-packages/mriqc/engine/plugin.py", line 456, in _async_callback
    result = args.result()
             ^^^^^^^^^^^^^
  File "/opt/conda/lib/python3.11/concurrent/futures/_base.py", line 449, in result
    return self.__get_result()
           ^^^^^^^^^^^^^^^^^^^
  File "/opt/conda/lib/python3.11/concurrent/futures/_base.py", line 401, in __get_result
    raise self._exception
concurrent.futures.process.BrokenProcessPool: A process in the process pool was terminated abruptly while the future was running or pending.
